<?xml version='1.0' encoding='utf-8'?>
<robot name="robot_">
    <!-- add more codes -->
  <material name="Grey">
    <color rgba="0.2 0.2 0.2 1.0"/>
  </material>

  <material name="Orange">
    <color rgba="1.0 0.423529411765 0.0392156862745 1.0"/>
  </material>

  <material name="Black">
    <color rgba="0 0 0 1.0"/>      
  </material>

<!-- <link name="world"/> -->

  <link name="base_link">
  </link>

  <joint name="joint_0" type="fixed">
    <parent link="base_link"/>
    <child link="link_0"/>
    <origin rpy="0 0 0" xyz="0 0 0"/>
    <axis xyz="0 0 0"/>
  </joint>

  <link name="link_0">
    <visual>
      <origin rpy="0 0 0" xyz="0 0 0"/>
      <geometry>
        <mesh filename="package://get_a/meshes/link_0.STL"/>
      </geometry>
      <material name="Orange"/>
    </visual>
  </link>

  <joint name="joint_1" type="revolute">
    <parent link="link_0"/>
    <child link="link_1"/>
    <origin rpy="0 0 0" xyz="0 0 0.02"/>
    <axis xyz="0 0 1"/>
    <limit lower="-2" upper="2" effort="0.5" velocity="0.5"/>
  </joint>

  <link name="link_1">
    <visual>
      <origin rpy="0 0 0" xyz="0 0 0"/>
      <geometry>
        <mesh filename="package://get_a/meshes/link_1.STL"/>
      </geometry>
      <material name="Black"/>
    </visual>
  </link>

 <joint name="joint_2" type="revolute">
    <parent link="link_1"/>
    <child link="link_2"/>
    <origin rpy="1.57079632679 0 0" xyz="0 0 1.3"/>
    <axis xyz="0 0 1"/>
    <limit lower="-0.01" upper="2.36" effort="0.5" velocity="0.5"/>
  </joint>

  <link name="link_2">
    <visual>
      <origin rpy="0 0 0" xyz="0 0 0"/>
      <geometry>
        <mesh filename="package://get_a/meshes/link_2.STL"/>
      </geometry>
      <material name="Orange"/>
    </visual>
  </link>

  <joint name="joint_3" type="revolute">
    <parent link="link_2"/>
    <child link="link_3"/>
    <origin rpy="0 0 0" xyz="1 0 0"/>
    <axis xyz="0 0 1"/>
    <limit lower="-1.5" upper="1" effort="0.5" velocity="0.5"/>
  </joint>

  <link name="link_3">
    <visual>
      <origin rpy="0 0 0" xyz="0 0 0"/>
      <geometry>
        <mesh filename="package://get_a/meshes/link_3.STL"/>
      </geometry>
      <material name="Black"/>
    </visual>
  </link> 

  <joint name="joint_eff" type="fixed">
    <parent link="link_3"/>
    <child link="end_effector"/>
    <origin rpy="1.57079632679 0 1.57079632679" xyz="0.8 0 0.0"/>
    <axis xyz="0 0 1"/>
  </joint>


  <link name="end_effector">
  </link>  

</robot>
